Workbook

Sheet Questions
A1: ID | B1: Sual | C1: A | D1: B | E1: C | F1: D | G1: Düzgün cavab | H1: Çətinlik | I1: Mövzu | J1: İzah | K1: Şəkil faylı | L1: Şəkil alt mətni | M1: Şəkil mənbəyi | N1: Şəkil lisenziyası | O1: Sual mənbəyi | P1: Status | Q1: Qeyd
A2: LIT-001 | B2: "Xəmsə" kimin əsəridir? | C2: Məhəmməd Füzuli | D2: Nəsimi | E2: Nizami Gəncəvi | F2: Xaqani Şirvani | G2: C | H2: Easy | I2: Klassik poeziya | J2: "Xəmsə" Nizami Gəncəvinin poemalarından ibarət məşhur toplusudur. | O2: https://az.wikipedia.org/wiki/Nizami_G%C9%99nc%C9%99vi | P2: Təsdiqlənib | Q2: Yoxlandı 16.09.2026: mənbədə "Xəmsə" ifadəsi ilə cavab təsdiqləndi.
A3: LIT-002 | B3: Azərbaycan türkcəsində "Leyli və Məcnun" poemasını yazan klassik şair kimdir? | C3: Məhəmməd Füzuli | D3: Molla Pənah Vaqif | E3: Nizami Gəncəvi | F3: Şah İsmayıl Xətai | G3: A | H3: Easy | I3: Klassik poeziya | J3: Füzuli "Leyli və Məcnun"u ana dilində yazmışdır; Nizaminin eyniadlı poeması fars dilindədir. | O3: https://az.wikipedia.org/wiki/M%C9%99h%C9%99mm%C9%99d_F%C3%BCzuli | P3: Təsdiqlənib | Q3: Yoxlandı 16.09.2026: mənbədə "Leyli və Məcnun" ifadəsi ilə cavab təsdiqləndi.
A4: LIT-003 | B4: "Ölülər" pyesinin müəllifi kimdir? | C4: Cəfər Cabbarlı | D4: Əbdürrəhim bəy Haqverdiyev | E4: Nəcəf bəy Vəzirov | F4: Cəlil Məmmədquluzadə | G4: D | H4: Easy | I4: Dramaturgiya | J4: "Ölülər" Cəlil Məmmədquluzadənin məşhur komediyasıdır. | O4: https://az.wikipedia.org/wiki/C%C9%99lil_M%C9%99mm%C9%99dquluzad%C9%99 | P4: Təsdiqlənib | Q4: Yoxlandı 16.09.2026: mənbədə "Ölülər" ifadəsi ilə cavab təsdiqləndi.
A5: LIT-004 | B5: "Hophopnamə" kimin şeirlər toplusudur? | C5: Seyid Əzim Şirvani | D5: Məhəmməd Hadi | E5: Abbas Səhhət | F5: Mirzə Ələkbər Sabir | G5: D | H5: Easy | I5: Satira | J5: Sabirin satirik şeirləri "Hophopnamə" adı ilə toplanmışdır. | O5: https://az.wikipedia.org/wiki/Mirz%C9%99_%C6%8Fl%C9%99kb%C9%99r_Sabir | P5: Təsdiqlənib | Q5: Yoxlandı 16.09.2026: mənbədə "Hophopnamə" ifadəsi ilə cavab təsdiqləndi.
A6: LIT-005 | B6: Qrafik portretdə təsvir olunan XIX–XX əsr satirik şairi kimdir? | C6: Seyid Əzim Şirvani | D6: Mirzə Ələkbər Sabir | E6: Məhəmməd Hadi | F6: Abbas Səhhət | G6: B | H6: Easy | I6: Portret | J6: Portretdə satirik şair Mirzə Ələkbər Sabir təsvir olunub. | K6: literature-001.webp | L6: Başında papaq olan, saqqallı kişinin qrafik portreti | M6: https://commons.wikimedia.org/wiki/File:Sabir.jpg | N6: Public domain (Wikimedia Commons) | O6: https://az.wikipedia.org/wiki/Mirz%C9%99_%C6%8Fl%C9%99kb%C9%99r_Sabir ; https://commons.wikimedia.org/wiki/File:Sabir.jpg | P6: Təsdiqlənib | Q6: Yoxlandı 16.09.2026: şəklin kimliyi Wikimedia Commons fayl təsvirində, məlumat az.wikipedia məqaləsində təsdiqləndi. Lisenziya Commons metaməlumatındandır.
A7: LIT-006 | B7: "Sevil" pyesinin müəllifi kimdir? | C7: Hüseyn Cavid | D7: Səməd Vurğun | E7: Cəfər Cabbarlı | F7: Mirzə İbrahimov | G7: C | H7: Easy | I7: Dramaturgiya | J7: "Sevil" Cəfər Cabbarlının qadın azadlığına həsr olunmuş pyesidir. | O7: https://az.wikipedia.org/wiki/C%C9%99f%C9%99r_Cabbarl%C4%B1 | P7: Təsdiqlənib | Q7: Yoxlandı 16.09.2026: mənbədə "Sevil" ifadəsi ilə cavab təsdiqləndi.
A8: LIT-007 | B8: "Vaqif" mənzum dramını kim yazmışdır? | C8: Səməd Vurğun | D8: Rəsul Rza | E8: Hüseyn Cavid | F8: Mikayıl Müşfiq | G8: A | H8: Easy | I8: Dramaturgiya | J8: "Vaqif" Səməd Vurğunun mənzum dramıdır. | O8: https://az.wikipedia.org/wiki/S%C9%99m%C9%99d_Vur%C4%9Fun | P8: Təsdiqlənib | Q8: Yoxlandı 16.09.2026: mənbədə "Vaqif" ifadəsi ilə cavab təsdiqləndi.
A9: LIT-008 | B9: "Koroğlu" dastanında Koroğlunun əsl adı nədir? | C9: Eyvaz | D9: Rövşən | E9: Həmzə | F9: Dəmirçioğlu | G9: B | H9: Easy | I9: Folklor | J9: Dastana görə Koroğlunun əsl adı Rövşəndir. | O9: https://az.wikipedia.org/wiki/Koro%C4%9Flu_dastan%C4%B1 | P9: Təsdiqlənib | Q9: Yoxlandı 16.09.2026: mənbədə "Rövşən" ifadəsi ilə cavab təsdiqləndi.
A10: LIT-009 | B10: "Şeyx Sənan" faciəsinin müəllifi kimdir? | C10: Nəriman Nərimanov | D10: Cəfər Cabbarlı | E10: Əbdürrəhim bəy Haqverdiyev | F10: Hüseyn Cavid | G10: D | H10: Easy | I10: Dramaturgiya | J10: "Şeyx Sənan" Hüseyn Cavidin məşhur faciəsidir. | O10: https://az.wikipedia.org/wiki/H%C3%BCseyn_Cavid | P10: Təsdiqlənib | Q10: Yoxlandı 16.09.2026: mənbədə "Şeyx Sənan" ifadəsi ilə cavab təsdiqləndi.
A11: LIT-010 | B11: Sepiya fotoşəkildə təsvir olunan romantik dramaturq kimdir? | C11: Abdulla Şaiq | D11: Hüseyn Cavid | E11: Əhməd Cavad | F11: Cəfər Cabbarlı | G11: B | H11: Easy | I11: Portret | J11: Fotoşəkildə dramaturq Hüseyn Cavid təsvir olunub. | K11: literature-002.webp | L11: Papaqlı, eynəkli və qalstuklu kişinin sepiya fotoportreti | M11: https://commons.wikimedia.org/wiki/File:Huseyn_Javid.jpg | N11: Public domain (Wikimedia Commons) | O11: https://az.wikipedia.org/wiki/H%C3%BCseyn_Cavid ; https://commons.wikimedia.org/wiki/File:Huseyn_Javid.jpg | P11: Təsdiqlənib | Q11: Yoxlandı 16.09.2026: şəklin kimliyi Wikimedia Commons fayl təsvirində, məlumat az.wikipedia məqaləsində təsdiqləndi. Lisenziya Commons metaməlumatındandır.
A12: LIT-011 | B12: "Kitabi-Dədə Qorqud"da Təpəgözü öldürən qəhrəman kimdir? | C12: Qazan xan | D12: Qaraca Çoban | E12: Beyrək | F12: Basat | G12: D | H12: Easy | I12: Folklor | J12: Təpəgözü Aruz Qocanın oğlu Basat öldürür. | O12: https://az.wikipedia.org/wiki/Kitabi-D%C9%99d%C9%99_Qorqud | P12: Təsdiqlənib | Q12: Yoxlandı 16.09.2026: mənbədə "Basat", "Təpəgöz" ifadəsi ilə cavab təsdiqləndi.
A13: LIT-012 | B13: "Koroğlu" dastanında Koroğlunun atının adı nədir? | C13: Qırat | D13: Səmənd | E13: Bozat | F13: Ağtulpar | G13: A | H13: Easy | I13: Folklor | J13: Koroğlunun məşhur atı Qıratdır. | O13: https://az.wikipedia.org/wiki/Q%C4%B1rat | P13: Təsdiqlənib | Q13: Yoxlandı 16.09.2026: mənbədə "Koroğlu" ifadəsi ilə cavab təsdiqləndi.
A14: LIT-013 | B14: "Əsli və Kərəm" dastanında Kərəmin sevdiyi qız kimdir? | C14: Nigar | D14: Əsli | E14: Telli | F14: Pəri | G14: B | H14: Easy | I14: Folklor | J14: Dastanın qəhrəmanları Kərəm və Əslidir. | O14: https://az.wikipedia.org/wiki/%C6%8Fsli_v%C9%99_K%C9%99r%C9%99m | P14: Təsdiqlənib | Q14: Yoxlandı 16.09.2026: mənbədə "Əsli" ifadəsi ilə cavab təsdiqləndi.
A15: LIT-014 | B15: "Molla Nəsrəddin" satirik jurnalının redaktoru kim idi? | C15: Mirzə Ələkbər Sabir | D15: Həsən bəy Zərdabi | E15: Cəlil Məmmədquluzadə | F15: Üzeyir Hacıbəyli | G15: C | H15: Easy | I15: Mətbuat | J15: Jurnalın naşiri və redaktoru Cəlil Məmmədquluzadə idi. | O15: https://az.wikipedia.org/wiki/Molla_N%C9%99sr%C9%99ddin_(jurnal) | P15: Təsdiqlənib | Q15: Yoxlandı 16.09.2026: mənbədə "Məmmədquluzadə" ifadəsi ilə cavab təsdiqləndi.
A16: LIT-015 | B16: 1942-ci ildə çəkilmiş bu fotoşəkildəki şair kimdir? | C16: Səməd Vurğun | D16: Rəsul Rza | E16: Süleyman Rüstəm | F16: Mikayıl Müşfiq | G16: A | H16: Easy | I16: Portret | J16: Fotoşəkil 1942-ci ildə çəkilib, şair Səməd Vurğunu təsvir edir. | K16: literature-003.webp | L16: Qıvrım saçlı, gülümsəyən, köynəyində nişanlar olan kişinin ağ-qara fotoportreti | M16: https://commons.wikimedia.org/wiki/File:Samad_Vurgun_(1942).jpg | N16: Public domain (Wikimedia Commons) | O16: https://az.wikipedia.org/wiki/S%C9%99m%C9%99d_Vur%C4%9Fun ; https://commons.wikimedia.org/wiki/File:Samad_Vurgun_(1942).jpg | P16: Təsdiqlənib | Q16: Yoxlandı 16.09.2026: şəklin kimliyi Wikimedia Commons fayl təsvirində, məlumat az.wikipedia məqaləsində təsdiqləndi. Lisenziya Commons metaməlumatındandır.
A17: LIT-016 | B17: Azərbaycan dilində ilk qəzet olan "Əkinçi"ni kim nəşr etmişdir? | C17: Həsən bəy Zərdabi | D17: Mirzə Fətəli Axundzadə | E17: Seyid Əzim Şirvani | F17: Əli bəy Hüseynzadə | G17: A | H17: Easy | I17: Mətbuat | J17: "Əkinçi" 1875-ci ildə Həsən bəy Zərdabi tərəfindən nəşr olunmuşdur. | O17: https://az.wikipedia.org/wiki/H%C9%99s%C9%99n_b%C9%99y_Z%C9%99rdabi | P17: Təsdiqlənib | Q17: Yoxlandı 16.09.2026: mənbədə "Əkinçi" ifadəsi ilə cavab təsdiqləndi.
A18: LIT-017 | B18: Azərbaycan Respublikasının Dövlət Himninin sözlərinin müəllifi kimdir? | C18: Məhəmməd Hadi | D18: Mikayıl Müşfiq | E18: Səməd Vurğun | F18: Əhməd Cavad | G18: D | H18: Easy | I18: XX əsr poeziyası | J18: Rəsmi mövqeyə görə himnin sözləri Əhməd Cavada, musiqisi Üzeyir Hacıbəyliyə məxsusdur (bəzi mənbələrdə Cəmo Cəbrayılbəylinin adı da çəkilir). | O18: https://az.wikipedia.org/wiki/Az%C9%99rbaycan_himni | P18: Təsdiqlənib | Q18: Yoxlandı 16.09.2026: mənbədə "Əhməd Cavad" ifadəsi ilə cavab təsdiqləndi.
A19: LIT-018 | B19: "Arşın mal alan" musiqili komediyasının müəllifi kimdir? | C19: Zülfüqar Hacıbəyov | D19: Üzeyir Hacıbəyli | E19: Müslüm Maqomayev | F19: Cəlil Məmmədquluzadə | G19: B | H19: Easy | I19: Dramaturgiya | J19: "Arşın mal alan" Üzeyir Hacıbəylinin musiqili komediyasıdır. | O19: https://az.wikipedia.org/wiki/Ar%C5%9F%C4%B1n_mal_alan_(operetta) | P19: Təsdiqlənib | Q19: Yoxlandı 16.09.2026: mənbədə "Hacıbəy" ifadəsi ilə cavab təsdiqləndi.
A20: LIT-019 | B20: Bakıdakı Azərbaycan Ədəbiyyatı Muzeyi hansı şairin adını daşıyır? | C20: Səməd Vurğun | D20: Məhəmməd Füzuli | E20: Nizami Gəncəvi | F20: Nəsimi | G20: C | H20: Easy | I20: Ədəbi mühit | J20: Muzeyin tam adı Nizami Gəncəvi adına Azərbaycan Ədəbiyyatı Muzeyidir. | O20: https://az.wikipedia.org/wiki/Nizami_G%C9%99nc%C9%99vi_ad%C4%B1na_Milli_Az%C9%99rbaycan_%C6%8Fd%C9%99biyyat%C4%B1_Muzeyi | P20: Təsdiqlənib | Q20: Yoxlandı 16.09.2026: mənbədə "Nizami Gəncəvi adına" ifadəsi ilə cavab təsdiqləndi.
A21: LIT-020 | B21: Təxminən 1920-ci ildə çəkilmiş bu fotoşəkildəki yazıçı kimdir? | C21: Firidun bəy Köçərli | D21: Əbdürrəhim bəy Haqverdiyev | E21: Nəriman Nərimanov | F21: Cəlil Məmmədquluzadə | G21: D | H21: Easy | I21: Portret | J21: Fotoşəkildə Cəlil Məmmədquluzadə təsvir olunub (təqr. 1920). | K21: literature-004.webp | L21: Bığlı, dik yaxalı köynək və pencək geyinmiş kişinin arxiv fotoportreti | M21: https://commons.wikimedia.org/wiki/File:Jalil_Mammadguluzadeh,_c._1920.jpg | N21: Public domain (Wikimedia Commons) | O21: https://az.wikipedia.org/wiki/C%C9%99lil_M%C9%99mm%C9%99dquluzad%C9%99 ; https://commons.wikimedia.org/wiki/File:Jalil_Mammadguluzadeh,_c._1920.jpg | P21: Təsdiqlənib | Q21: Yoxlandı 16.09.2026: şəklin kimliyi Wikimedia Commons fayl təsvirində, məlumat az.wikipedia məqaləsində təsdiqləndi. Lisenziya Commons metaməlumatındandır.
A22: LIT-021 | B22: "Tıq-tıq xanım" əsərinin müəllifi kimdir? | C22: Mirzə Ələkbər Sabir | D22: Abbas Səhhət | E22: Süleyman Sani Axundov | F22: Abdulla Şaiq | G22: D | H22: Easy | I22: Uşaq ədəbiyyatı | J22: "Tıq-tıq xanım" Abdulla Şaiqin uşaqlar üçün yazdığı əsərdir. | O22: https://az.wikipedia.org/wiki/Abdulla_%C5%9Eaiq | P22: Təsdiqlənib | Q22: Yoxlandı 16.09.2026: mənbədə "Tıq-tıq xanım" ifadəsi ilə cavab təsdiqləndi.
A23: LIT-022 | B23: "Xətai" təxəllüsü ilə şeirlər yazan hökmdar kimdir? | C23: Şah İsmayıl Səfəvi | D23: Qazi Bürhanəddin | E23: Cahan şah | F23: Şah Təhmasib | G23: A | H23: Easy | I23: Klassik poeziya | J23: Səfəvi dövlətinin banisi I Şah İsmayıl "Xətai" təxəllüsü ilə yazırdı. | O23: https://az.wikipedia.org/wiki/I_%C4%B0smay%C4%B1l | P23: Təsdiqlənib | Q23: Yoxlandı 16.09.2026: mənbədə "Xətai" ifadəsi ilə cavab təsdiqləndi.
A24: LIT-023 | B24: "Kitabi-Dədə Qorqud"da boyları qoşub söyləyən müdrik ozan kimdir? | C24: Bayandır xan | D24: Aruz Qoca | E24: Dədə Qorqud | F24: Qazan xan | G24: C | H24: Easy | I24: Folklor | J24: Boyların sonunda Dədə Qorqud gəlib boy boylayır, soy soylayır. | O24: https://az.wikipedia.org/wiki/D%C9%99d%C9%99_Qorqud | P24: Təsdiqlənib | Q24: Yoxlandı 16.09.2026: mənbədə "ozan" ifadəsi ilə cavab təsdiqləndi.
A25: LIT-024 | B25: "Aşıq Qərib" dastanında Qəribin sevgilisi kimdir? | C25: Nigar | D25: Gülnar | E25: Şahsənəm | F25: Pərizad | G25: C | H25: Easy | I25: Folklor | J25: Dastanın əsas qəhrəmanları Aşıq Qərib və Şahsənəmdir. | O25: https://az.wikipedia.org/wiki/A%C5%9F%C4%B1q_Q%C9%99rib_dastan%C4%B1 | P25: Təsdiqlənib | Q25: Yoxlandı 16.09.2026: mənbədə "Şahsənəm" ifadəsi ilə cavab təsdiqləndi.
A26: LIT-025 | B26: Köhnə fotoşəkildə təsvir olunan XIX əsr şairəsi kimdir? | C26: Xurşidbanu Natəvan | D26: Heyran xanım | E26: Aşıq Pəri | F26: Məhsəti Gəncəvi | G26: A | H26: Easy | I26: Portret | J26: Fotoşəkildə şairə Xurşidbanu Natəvan təsvir olunub. | K26: literature-005.webp | L26: Başına naxışlı örpək örtmüş qadının köhnə fotoşəkli | M26: https://commons.wikimedia.org/wiki/File:Natavan.jpg | N26: Public domain (Wikimedia Commons) | O26: https://az.wikipedia.org/wiki/Xur%C5%9Fidbanu_Nat%C9%99van ; https://commons.wikimedia.org/wiki/File:Natavan.jpg | P26: Təsdiqlənib | Q26: Yoxlandı 16.09.2026: şəklin kimliyi Wikimedia Commons fayl təsvirində, məlumat az.wikipedia məqaləsində təsdiqləndi. Lisenziya Commons metaməlumatındandır.
A27: LIT-026 | B27: "Cırtdan" hansı janra aiddir? | C27: Mənzum dram | D27: Dastan | E27: Rübai | F27: Nağıl | G27: D | H27: Easy | I27: Folklor | J27: "Cırtdan" Azərbaycan xalq nağılıdır. | O27: https://az.wikipedia.org/wiki/C%C4%B1rtdan | P27: Təsdiqlənib | Q27: Yoxlandı 16.09.2026: mənbədə "nağıl" ifadəsi ilə cavab təsdiqləndi.
A28: LIT-027 | B28: Laylı, bayatı və oxşama hansı ədəbiyyat sahəsinə aiddir? | C28: Şifahi xalq ədəbiyyatı | D28: Klassik divan ədəbiyyatı | E28: Maarifçi publisistika | F28: Sovet dövrü dramaturgiyası | G28: A | H28: Easy | I28: Folklor | J28: Bunlar folklorun lirik janrlarıdır. | O28: https://az.wikipedia.org/wiki/Bayat%C4%B1 | P28: Təsdiqlənib | Q28: Yoxlandı 16.09.2026: mənbədə "xalq" ifadəsi ilə cavab təsdiqləndi.
A29: LIT-028 | B29: Rübai neçə misradan ibarətdir? | C29: 14 | D29: 2 | E29: 4 | F29: 5 | G29: C | H29: Easy | I29: Ədəbiyyat nəzəriyyəsi | J29: Rübai dörd misralı şeir formasıdır. | O29: https://az.wikipedia.org/wiki/R%C3%BCbai | P29: Təsdiqlənib | Q29: Yoxlandı 16.09.2026: mənbədə "dörd misra" ifadəsi ilə cavab təsdiqləndi.
A30: LIT-029 | B30: Beyt neçə misradan ibarətdir? | C30: 2 | D30: 6 | E30: 3 | F30: 4 | G30: A | H30: Easy | I30: Ədəbiyyat nəzəriyyəsi | J30: Beyt iki misradan ibarət şeir vahididir. | O30: https://az.wikipedia.org/wiki/Beyt | P30: Təsdiqlənib | Q30: Yoxlandı 16.09.2026: mənbədə "2 misra" ifadəsi ilə cavab təsdiqləndi.
A31: LIT-030 | B31: Bu rəsm hansı klassik şairi təsvir edir? | C31: Nizami Gəncəvi | D31: Nəsimi | E31: Məhəmməd Füzuli | F31: Şah İsmayıl Xətai | G31: C | H31: Easy | I31: Portret | J31: Rəsm Əzim Əzimzadənin Füzuli portretidir (1914). | K31: literature-006.webp | L31: Ağ saqqallı, naxışlı papaqlı, xəz yaxalı xalat geyinmiş qoca kişinin rəngli rəsmi | M31: https://commons.wikimedia.org/wiki/File:Portrait_of_Azerbaijani_poet_Fuzuli_by_Azimzade.jpg | N31: Public domain (Wikimedia Commons) | O31: https://az.wikipedia.org/wiki/M%C9%99h%C9%99mm%C9%99d_F%C3%BCzuli ; https://commons.wikimedia.org/wiki/File:Portrait_of_Azerbaijani_poet_Fuzuli_by_Azimzade.jpg | P31: Təsdiqlənib | Q31: Yoxlandı 16.09.2026: şəklin kimliyi Wikimedia Commons fayl təsvirində, məlumat az.wikipedia məqaləsində təsdiqləndi. Lisenziya Commons metaməlumatındandır.
A32: LIT-031 | B32: Qoşma hansı vəzndə yazılır? | C32: Heca vəzni | D32: Sərbəst vəzn | E32: Ağ şeir | F32: Əruz vəzni | G32: A | H32: Easy | I32: Ədəbiyyat nəzəriyyəsi | J32: Qoşma aşıq şeirinin heca vəznində yazılan əsas formasıdır. | O32: https://az.wikipedia.org/wiki/Qo%C5%9Fma_(%C9%99d%C9%99biyyat) | P32: Təsdiqlənib | Q32: Yoxlandı 16.09.2026: mənbədə "heca" ifadəsi ilə cavab təsdiqləndi.
A33: LIT-032 | B33: Nizami Gəncəvi hansı əsrdə yaşamışdır? | C33: XIV əsr | D33: XVI əsr | E33: X əsr | F33: XII əsr | G33: D | H33: Easy | I33: Klassik poeziya | J33: Nizami təxminən 1141–1209-cu illərdə yaşamışdır. | O33: https://az.wikipedia.org/wiki/Nizami_G%C9%99nc%C9%99vi | P33: Təsdiqlənib | Q33: Yoxlandı 16.09.2026: mənbədə "1141" ifadəsi ilə cavab təsdiqləndi.
A34: LIT-033 | B34: Hazırcavab lətifələri ilə tanınan xalq obrazı kimdir? | C34: Hacı Qara | D34: Molla Nəsrəddin | E34: Məşədi İbad | F34: Cırtdan | G34: B | H34: Easy | I34: Folklor | J34: Molla Nəsrəddin lətifələrin məşhur qəhrəmanıdır. | O34: https://az.wikipedia.org/wiki/Molla_N%C9%99sr%C9%99ddin | P34: Təsdiqlənib | Q34: Yoxlandı 16.09.2026: mənbədə "lətifə" ifadəsi ilə cavab təsdiqləndi.
A35: LIT-034 | B35: Aşıqların ifa zamanı çaldığı əsas musiqi aləti hansıdır? | C35: Saz | D35: Kamança | E35: Qanun | F35: Tar | G35: A | H35: Easy | I35: Folklor | J35: Aşıq sənəti sazla ifa olunur. | O35: https://az.wikipedia.org/wiki/Saz | P35: Təsdiqlənib | Q35: Yoxlandı 16.09.2026: mənbədə "aşıq" ifadəsi ilə cavab təsdiqləndi.
A36: LIT-035 | B36: Şəkildəki məqbərə hansı şairin xatirəsinə ucaldılmışdır? | C36: Qətran Təbrizi | D36: Məhsəti Gəncəvi | E36: Xaqani Şirvani | F36: Nizami Gəncəvi | G36: D | H36: Easy | I36: Abidə | J36: Şəkildə Gəncədəki Nizami məqbərəsi təsvir olunub. | K36: literature-007.webp | L36: Açıq səma altında geniş meydanın ortasında yüksələn silindrik daş məqbərə | M36: https://commons.wikimedia.org/wiki/File:Nizami_Ganjavi_mausoleum_in_Ganja,_Azerbaijan_2.JPG | N36: CC BY-SA 3.0 — müəllif: Wertuose (https://creativecommons.org/licenses/by-sa/3.0) | O36: https://az.wikipedia.org/wiki/Nizami_m%C9%99qb%C9%99r%C9%99si ; https://commons.wikimedia.org/wiki/File:Nizami_Ganjavi_mausoleum_in_Ganja,_Azerbaijan_2.JPG | P36: Təsdiqlənib | Q36: Yoxlandı 16.09.2026: şəklin kimliyi Wikimedia Commons fayl təsvirində, məlumat az.wikipedia məqaləsində təsdiqləndi. Lisenziya Commons metaməlumatındandır.
A37: LIT-036 | B37: "Kitabi-Dədə Qorqud"da Dəli Domrul kiminlə vuruşmaq istəyir? | C37: Təpəgöz | D37: Əzrayıl | E37: Qazan xan | F37: Şöklü Məlik | G37: B | H37: Easy | I37: Folklor | J37: Dəli Domrul can alan Əzrayılla vuruşmağa çıxır. | O37: https://az.wikipedia.org/wiki/Kitabi-D%C9%99d%C9%99_Qorqud | P37: Təsdiqlənib | Q37: Yoxlandı 16.09.2026: mənbədə "Domrul", "Əzrayıl" ifadəsi ilə cavab təsdiqləndi.
A38: LIT-037 | B38: "Məndə sığar iki cahan, mən bu cahana sığmazam" misrasının müəllifi kimdir? | C38: Şah İsmayıl Xətai | D38: Qazi Bürhanəddin | E38: Məhəmməd Füzuli | F38: Nəsimi | G38: D | H38: Easy | I38: Klassik poeziya | J38: Bu məşhur misra Nəsiminin qəzəlindəndir. | O38: https://az.wikipedia.org/wiki/M%C9%99nd%C9%99_s%C4%B1%C4%9Far_iki_cahan%2C_m%C9%99n_bu_cahan%C9%99_s%C4%B1%C4%9Fmazam | P38: Təsdiqlənib | Q38: Yoxlandı 16.09.2026: mənbədə "Nəsimi" ifadəsi ilə cavab təsdiqləndi.
A39: LIT-038 | B39: Xalq arasında "Xan qızı" adı ilə tanınan şairə kimdir? | C39: Heyran xanım | D39: Aşıq Pəri | E39: Məhsəti Gəncəvi | F39: Xurşidbanu Natəvan | G39: D | H39: Easy | I39: Klassik poeziya | J39: Qarabağ xanı Mehdiqulu xanın qızı Natəvan "Xan qızı" kimi tanınırdı. | O39: https://az.wikipedia.org/wiki/Xur%C5%9Fidbanu_Nat%C9%99van | P39: Təsdiqlənib | Q39: Yoxlandı 16.09.2026: mənbədə "Xan qızı" ifadəsi ilə cavab təsdiqləndi.
A40: LIT-039 | B40: Hüseyn Cavid hansı şəhərdə anadan olmuşdur? | C40: Naxçıvan | D40: Gəncə | E40: Şuşa | F40: Şamaxı | G40: A | H40: Easy | I40: Dramaturgiya | J40: Hüseyn Cavid 1882-ci ildə Naxçıvanda doğulmuşdur. | O40: https://az.wikipedia.org/wiki/H%C3%BCseyn_Cavid | P40: Təsdiqlənib | Q40: Yoxlandı 16.09.2026: mənbədə "Naxçıvan" ifadəsi ilə cavab təsdiqləndi.
...

Sheet Yoxlama
A1: Ədəbiyyat Dünyası — doldurma yoxlaması
A3: Göstərici | B3: Cari | C3: Hədəf | D3: Nəticə
A4: Ümumi sual | B4: =COUNTA(Questions!B2:B151) -> 150 | C4: 150 | D4: =IF(B4=C4,"OK","Yoxla") -> OK
A5: Easy | B5: =COUNTIF(Questions!H2:H151,"Easy") -> 45 | C5: 45 | D5: =IF(B5=C5,"OK","Yoxla") -> OK
A6: Medium | B6: =COUNTIF(Questions!H2:H151,"Medium") -> 60 | C6: 60 | D6: =IF(B6=C6,"OK","Yoxla") -> OK
A7: Hard | B7: =COUNTIF(Questions!H2:H151,"Hard") -> 45 | C7: 45 | D7: =IF(B7=C7,"OK","Yoxla") -> OK
A8: Şəkilli sual | B8: =COUNTIF(Questions!K2:K151,"<>") -> 30 | C8: 30 | D8: =IF(B8=C8,"OK","Yoxla") -> OK
A9: Mətnli sual | B9: =COUNTA(Questions!B2:B151)-COUNTIF(Questions!K2:K151,"<>") -> 120 | C9: 120 | D9: =IF(B9=C9,"OK","Yoxla") -> OK
A10: Şəkilli Easy | B10: =COUNTIFS(Questions!H2:H151,"Easy",Questions!K2:K151,"<>") -> 9 | C10: 9 | D10: =IF(B10=C10,"OK","Yoxla") -> OK
A11: Şəkilli Medium | B11: =COUNTIFS(Questions!H2:H151,"Medium",Questions!K2:K151,"<>") -> 12 | C11: 12 | D11: =IF(B11=C11,"OK","Yoxla") -> OK
A12: Şəkilli Hard | B12: =COUNTIFS(Questions!H2:H151,"Hard",Questions!K2:K151,"<>") -> 9 | C12: 9 | D12: =IF(B12=C12,"OK","Yoxla") -> OK
A13: Düzgün cavab A | B13: =COUNTIF(Questions!G2:G151,"A") -> 38 | C13: 38 | D13: =IF(B13=C13,"OK","Yoxla") -> OK
A14: Düzgün cavab B | B14: =COUNTIF(Questions!G2:G151,"B") -> 38 | C14: 38 | D14: =IF(B14=C14,"OK","Yoxla") -> OK
A15: Düzgün cavab C | B15: =COUNTIF(Questions!G2:G151,"C") -> 37 | C15: 37 | D15: =IF(B15=C15,"OK","Yoxla") -> OK
A16: Düzgün cavab D | B16: =COUNTIF(Questions!G2:G151,"D") -> 37 | C16: 37 | D16: =IF(B16=C16,"OK","Yoxla") -> OK
A17: Mənbəsiz sual | B17: =COUNTA(Questions!B2:B151)-COUNTIF(Questions!O2:O151,"<>") -> 0 | C17: 0 | D17: =IF(B17=C17,"OK","Yoxla") -> OK
A18: Mənbəsiz şəkil | B18: =COUNTIF(Questions!K2:K151,"<>")-COUNTIFS(Questions!K2:K151,"<>",Questions!M2:M151,"<>") -> 0 | C18: 0 | D18: =IF(B18=C18,"OK","Yoxla") -> OK
A19: Lisenziyasız şəkil | B19: =COUNTIF(Questions!K2:K151,"<>")-COUNTIFS(Questions!K2:K151,"<>",Questions!N2:N151,"<>") -> 0 | C19: 0 | D19: =IF(B19=C19,"OK","Yoxla") -> OK
A20: Alt mətni olmayan şəkil | B20: =COUNTIF(Questions!K2:K151,"<>")-COUNTIFS(Questions!K2:K151,"<>",Questions!L2:L151,"<>") -> 0 | C20: 0 | D20: =IF(B20=C20,"OK","Yoxla") -> OK
A23: Gözləyir | B23: =COUNTIFS(Questions!B2:B151,"<>",Questions!P2:P151,"Gözləyir") -> 0
A24: Təsdiqlənib | B24: =COUNTIFS(Questions!B2:B151,"<>",Questions!P2:P151,"Təsdiqlənib") -> 150
A25: Rədd edilib | B25: =COUNTIFS(Questions!B2:B151,"<>",Questions!P2:P151,"Rədd edilib") -> 0
A27: Qeyd: Qırmızı ilə işarələnən nəticələr hədəfdən fərqlənir. Questions səhifəsində eyni ID və ya eyni sual təkrarlanarsa hüceyrə qırmızı görünəcək.

Sheet Təlimat
A1: Ədəbiyyat Dünyası sual bankı — doldurma qaydaları
A3: Bölmə | B3: Qayda
A4: Sual sayı | B4: Dəqiq 150 sual: 45 Easy, 60 Medium, 45 Hard.
A5: Şəkil sayı | B5: 30 şəkilli sual: 9 Easy, 12 Medium, 9 Hard. Qalan 120 sual mətnli olmalıdır.
A6: ID | B6: ID-lər hazırdır: LIT-001–LIT-150. Dəyişdirməyin və təkrarlamayın.
A7: Düzgün cavab | B7: Yalnız A, B, C və ya D seçin. Hədəf: 38 / 38 / 37 / 37.
A8: Çətinlik | B8: Yalnız Easy, Medium və ya Hard seçin.
A9: Status | B9: İlkin Gözləyir. Fakt və mənbə yoxlandıqdan sonra Təsdiqlənib seçin.
A10: Bir sətir | B10: Hər sətirdə yalnız bir sual olsun. Hüceyrələri birləşdirməyin, gizli sətir yaratmayın.
A11: Mənbə | B11: Hər sual üçün birbaşa və etibarlı mənbə yazın. Ana səhifə və axtarış nəticəsi linki kifayət deyil.
A12: Şəkil | B12: Şəkli Excel-ə yerləşdirməyin. images qovluğunda ayrıca saxlayın.
A13: Şəkil adı | B13: Neytral ad istifadə edin: literature-001.jpg və s. Fayl adı cavabı açıqlamasın.
A14: Alt mətn | B14: Neytral təsvir yazın. Məsələn: Klassik geyimli ədibin portreti. Cavabın adını yazmayın.
... A19: Qovluq | B19: edebiyyat-dunyasi.xlsx və images/ qovluğunu birlikdə təhvil verin.
